{
 "cells": [
  {
   "attachments": {},
   "cell_type": "markdown",
   "metadata": {},
   "source": [
    "# Instalações das bibliotecas\n"
   ]
  },
  {
   "cell_type": "code",
   "execution_count": 1,
   "metadata": {},
   "outputs": [
    {
     "name": "stdout",
     "output_type": "stream",
     "text": [
      "\u001b[33mWARNING: Retrying (Retry(total=0, connect=None, read=None, redirect=None, status=None)) after connection broken by 'SSLError(\"Can't connect to HTTPS URL because the SSL module is not available.\")': /simple/nbformat/\u001b[0m\u001b[33m\n",
      "\u001b[0mCould not fetch URL https://pypi.org/simple/nbformat/: There was a problem confirming the ssl certificate: HTTPSConnectionPool(host='pypi.org', port=443): Max retries exceeded with url: /simple/nbformat/ (Caused by SSLError(\"Can't connect to HTTPS URL because the SSL module is not available.\")) - skipping\n",
      "Requirement already satisfied: fastjsonschema in /Users/carlosroberto/Documentos/Projetos/.conda/lib/python3.11/site-packages (from nbformat) (2.16.2)\n",
      "Requirement already satisfied: jsonschema>=2.6 in /Users/carlosroberto/Documentos/Projetos/.conda/lib/python3.11/site-packages (from nbformat) (4.17.3)\n",
      "Requirement already satisfied: jupyter-core in /Users/carlosroberto/Documentos/Projetos/.conda/lib/python3.11/site-packages (from nbformat) (5.3.0)\n",
      "Requirement already satisfied: traitlets>=5.1 in /Users/carlosroberto/Documentos/Projetos/.conda/lib/python3.11/site-packages (from nbformat) (5.9.0)\n",
      "Requirement already satisfied: attrs>=17.4.0 in /Users/carlosroberto/Documentos/Projetos/.conda/lib/python3.11/site-packages (from jsonschema>=2.6->nbformat) (23.1.0)\n",
      "Requirement already satisfied: pyrsistent!=0.17.0,!=0.17.1,!=0.17.2,>=0.14.0 in /Users/carlosroberto/Documentos/Projetos/.conda/lib/python3.11/site-packages (from jsonschema>=2.6->nbformat) (0.19.3)\n",
      "Requirement already satisfied: platformdirs>=2.5 in /Users/carlosroberto/Documentos/Projetos/.conda/lib/python3.11/site-packages (from jupyter-core->nbformat) (3.8.0)\n",
      "\u001b[33mWARNING: pip is configured with locations that require TLS/SSL, however the ssl module in Python is not available.\u001b[0m\u001b[33m\n",
      "\u001b[0mRequirement already satisfied: pandas in /Users/carlosroberto/Documentos/Projetos/.conda/lib/python3.11/site-packages (2.0.3)\n",
      "\u001b[33mWARNING: Retrying (Retry(total=4, connect=None, read=None, redirect=None, status=None)) after connection broken by 'SSLError(\"Can't connect to HTTPS URL because the SSL module is not available.\")': /simple/pandas/\u001b[0m\u001b[33m\n",
      "\u001b[0m\u001b[33mWARNING: Retrying (Retry(total=3, connect=None, read=None, redirect=None, status=None)) after connection broken by 'SSLError(\"Can't connect to HTTPS URL because the SSL module is not available.\")': /simple/pandas/\u001b[0m\u001b[33m\n",
      "\u001b[0m\u001b[33mWARNING: Retrying (Retry(total=2, connect=None, read=None, redirect=None, status=None)) after connection broken by 'SSLError(\"Can't connect to HTTPS URL because the SSL module is not available.\")': /simple/pandas/\u001b[0m\u001b[33m\n",
      "\u001b[0m\u001b[33mWARNING: Retrying (Retry(total=1, connect=None, read=None, redirect=None, status=None)) after connection broken by 'SSLError(\"Can't connect to HTTPS URL because the SSL module is not available.\")': /simple/pandas/\u001b[0m\u001b[33m\n",
      "\u001b[0m\u001b[33mWARNING: Retrying (Retry(total=0, connect=None, read=None, redirect=None, status=None)) after connection broken by 'SSLError(\"Can't connect to HTTPS URL because the SSL module is not available.\")': /simple/pandas/\u001b[0m\u001b[33m\n",
      "\u001b[0mCould not fetch URL https://pypi.org/simple/pandas/: There was a problem confirming the ssl certificate: HTTPSConnectionPool(host='pypi.org', port=443): Max retries exceeded with url: /simple/pandas/ (Caused by SSLError(\"Can't connect to HTTPS URL because the SSL module is not available.\")) - skipping\n",
      "Requirement already satisfied: python-dateutil>=2.8.2 in /Users/carlosroberto/Documentos/Projetos/.conda/lib/python3.11/site-packages (from pandas) (2.8.2)\n",
      "Requirement already satisfied: pytz>=2020.1 in /Users/carlosroberto/Documentos/Projetos/.conda/lib/python3.11/site-packages (from pandas) (2023.3)\n",
      "Requirement already satisfied: tzdata>=2022.1 in /Users/carlosroberto/Documentos/Projetos/.conda/lib/python3.11/site-packages (from pandas) (2023.3)\n",
      "Requirement already satisfied: numpy>=1.21.0 in /Users/carlosroberto/Documentos/Projetos/.conda/lib/python3.11/site-packages (from pandas) (1.23.5)\n",
      "Requirement already satisfied: six>=1.5 in /Users/carlosroberto/Documentos/Projetos/.conda/lib/python3.11/site-packages (from python-dateutil>=2.8.2->pandas) (1.16.0)\n",
      "\u001b[33mWARNING: pip is configured with locations that require TLS/SSL, however the ssl module in Python is not available.\u001b[0m\u001b[33m\n",
      "\u001b[0mRequirement already satisfied: matplotlib in /Users/carlosroberto/Documentos/Projetos/.conda/lib/python3.11/site-packages (3.7.1)\n",
      "\u001b[33mWARNING: Retrying (Retry(total=4, connect=None, read=None, redirect=None, status=None)) after connection broken by 'SSLError(\"Can't connect to HTTPS URL because the SSL module is not available.\")': /simple/matplotlib/\u001b[0m\u001b[33m\n",
      "\u001b[0m\u001b[33mWARNING: Retrying (Retry(total=3, connect=None, read=None, redirect=None, status=None)) after connection broken by 'SSLError(\"Can't connect to HTTPS URL because the SSL module is not available.\")': /simple/matplotlib/\u001b[0m\u001b[33m\n",
      "\u001b[0m\u001b[33mWARNING: Retrying (Retry(total=2, connect=None, read=None, redirect=None, status=None)) after connection broken by 'SSLError(\"Can't connect to HTTPS URL because the SSL module is not available.\")': /simple/matplotlib/\u001b[0m\u001b[33m\n",
      "\u001b[0m\u001b[33mWARNING: Retrying (Retry(total=1, connect=None, read=None, redirect=None, status=None)) after connection broken by 'SSLError(\"Can't connect to HTTPS URL because the SSL module is not available.\")': /simple/matplotlib/\u001b[0m\u001b[33m\n",
      "\u001b[0m\u001b[33mWARNING: Retrying (Retry(total=0, connect=None, read=None, redirect=None, status=None)) after connection broken by 'SSLError(\"Can't connect to HTTPS URL because the SSL module is not available.\")': /simple/matplotlib/\u001b[0m\u001b[33m\n",
      "\u001b[0mCould not fetch URL https://pypi.org/simple/matplotlib/: There was a problem confirming the ssl certificate: HTTPSConnectionPool(host='pypi.org', port=443): Max retries exceeded with url: /simple/matplotlib/ (Caused by SSLError(\"Can't connect to HTTPS URL because the SSL module is not available.\")) - skipping\n",
      "Requirement already satisfied: contourpy>=1.0.1 in /Users/carlosroberto/Documentos/Projetos/.conda/lib/python3.11/site-packages (from matplotlib) (1.1.0)\n",
      "Requirement already satisfied: cycler>=0.10 in /Users/carlosroberto/Documentos/Projetos/.conda/lib/python3.11/site-packages (from matplotlib) (0.11.0)\n",
      "Requirement already satisfied: fonttools>=4.22.0 in /Users/carlosroberto/Documentos/Projetos/.conda/lib/python3.11/site-packages (from matplotlib) (4.40.0)\n",
      "Requirement already satisfied: kiwisolver>=1.0.1 in /Users/carlosroberto/Documentos/Projetos/.conda/lib/python3.11/site-packages (from matplotlib) (1.4.4)\n",
      "Requirement already satisfied: numpy>=1.20 in /Users/carlosroberto/Documentos/Projetos/.conda/lib/python3.11/site-packages (from matplotlib) (1.23.5)\n",
      "Requirement already satisfied: packaging>=20.0 in /Users/carlosroberto/Documentos/Projetos/.conda/lib/python3.11/site-packages (from matplotlib) (23.1)\n",
      "Requirement already satisfied: pillow>=6.2.0 in /Users/carlosroberto/Documentos/Projetos/.conda/lib/python3.11/site-packages (from matplotlib) (9.5.0)\n",
      "Requirement already satisfied: pyparsing>=2.3.1 in /Users/carlosroberto/Documentos/Projetos/.conda/lib/python3.11/site-packages (from matplotlib) (3.1.0)\n",
      "Requirement already satisfied: python-dateutil>=2.7 in /Users/carlosroberto/Documentos/Projetos/.conda/lib/python3.11/site-packages (from matplotlib) (2.8.2)\n",
      "Requirement already satisfied: six>=1.5 in /Users/carlosroberto/Documentos/Projetos/.conda/lib/python3.11/site-packages (from python-dateutil>=2.7->matplotlib) (1.16.0)\n",
      "\u001b[33mWARNING: pip is configured with locations that require TLS/SSL, however the ssl module in Python is not available.\u001b[0m\u001b[33m\n",
      "\u001b[0mRequirement already satisfied: regex in /Users/carlosroberto/Documentos/Projetos/.conda/lib/python3.11/site-packages (2023.6.3)\n",
      "\u001b[33mWARNING: Retrying (Retry(total=4, connect=None, read=None, redirect=None, status=None)) after connection broken by 'SSLError(\"Can't connect to HTTPS URL because the SSL module is not available.\")': /simple/regex/\u001b[0m\u001b[33m\n",
      "\u001b[0m\u001b[33mWARNING: Retrying (Retry(total=3, connect=None, read=None, redirect=None, status=None)) after connection broken by 'SSLError(\"Can't connect to HTTPS URL because the SSL module is not available.\")': /simple/regex/\u001b[0m\u001b[33m\n",
      "\u001b[0m\u001b[33mWARNING: Retrying (Retry(total=2, connect=None, read=None, redirect=None, status=None)) after connection broken by 'SSLError(\"Can't connect to HTTPS URL because the SSL module is not available.\")': /simple/regex/\u001b[0m\u001b[33m\n",
      "\u001b[0m\u001b[33mWARNING: Retrying (Retry(total=1, connect=None, read=None, redirect=None, status=None)) after connection broken by 'SSLError(\"Can't connect to HTTPS URL because the SSL module is not available.\")': /simple/regex/\u001b[0m\u001b[33m\n",
      "\u001b[0m\u001b[33mWARNING: Retrying (Retry(total=0, connect=None, read=None, redirect=None, status=None)) after connection broken by 'SSLError(\"Can't connect to HTTPS URL because the SSL module is not available.\")': /simple/regex/\u001b[0m\u001b[33m\n",
      "\u001b[0mCould not fetch URL https://pypi.org/simple/regex/: There was a problem confirming the ssl certificate: HTTPSConnectionPool(host='pypi.org', port=443): Max retries exceeded with url: /simple/regex/ (Caused by SSLError(\"Can't connect to HTTPS URL because the SSL module is not available.\")) - skipping\n",
      "\u001b[33mWARNING: pip is configured with locations that require TLS/SSL, however the ssl module in Python is not available.\u001b[0m\u001b[33m\n",
      "\u001b[0mRequirement already satisfied: keras in /Users/carlosroberto/Documentos/Projetos/.conda/lib/python3.11/site-packages (2.13.1)\n",
      "\u001b[33mWARNING: Retrying (Retry(total=4, connect=None, read=None, redirect=None, status=None)) after connection broken by 'SSLError(\"Can't connect to HTTPS URL because the SSL module is not available.\")': /simple/keras/\u001b[0m\u001b[33m\n",
      "\u001b[0m\u001b[33mWARNING: Retrying (Retry(total=3, connect=None, read=None, redirect=None, status=None)) after connection broken by 'SSLError(\"Can't connect to HTTPS URL because the SSL module is not available.\")': /simple/keras/\u001b[0m\u001b[33m\n",
      "\u001b[0m\u001b[33mWARNING: Retrying (Retry(total=2, connect=None, read=None, redirect=None, status=None)) after connection broken by 'SSLError(\"Can't connect to HTTPS URL because the SSL module is not available.\")': /simple/keras/\u001b[0m\u001b[33m\n",
      "\u001b[0m\u001b[33mWARNING: Retrying (Retry(total=1, connect=None, read=None, redirect=None, status=None)) after connection broken by 'SSLError(\"Can't connect to HTTPS URL because the SSL module is not available.\")': /simple/keras/\u001b[0m\u001b[33m\n",
      "\u001b[0m\u001b[33mWARNING: Retrying (Retry(total=0, connect=None, read=None, redirect=None, status=None)) after connection broken by 'SSLError(\"Can't connect to HTTPS URL because the SSL module is not available.\")': /simple/keras/\u001b[0m\u001b[33m\n",
      "\u001b[0mCould not fetch URL https://pypi.org/simple/keras/: There was a problem confirming the ssl certificate: HTTPSConnectionPool(host='pypi.org', port=443): Max retries exceeded with url: /simple/keras/ (Caused by SSLError(\"Can't connect to HTTPS URL because the SSL module is not available.\")) - skipping\n",
      "\u001b[33mWARNING: pip is configured with locations that require TLS/SSL, however the ssl module in Python is not available.\u001b[0m\u001b[33m\n",
      "\u001b[0mRequirement already satisfied: tensorflow in /Users/carlosroberto/Documentos/Projetos/.conda/lib/python3.11/site-packages (2.13.0rc2)\n",
      "\u001b[33mWARNING: Retrying (Retry(total=4, connect=None, read=None, redirect=None, status=None)) after connection broken by 'SSLError(\"Can't connect to HTTPS URL because the SSL module is not available.\")': /simple/tensorflow/\u001b[0m\u001b[33m\n",
      "\u001b[0m\u001b[33mWARNING: Retrying (Retry(total=3, connect=None, read=None, redirect=None, status=None)) after connection broken by 'SSLError(\"Can't connect to HTTPS URL because the SSL module is not available.\")': /simple/tensorflow/\u001b[0m\u001b[33m\n",
      "\u001b[0m\u001b[33mWARNING: Retrying (Retry(total=2, connect=None, read=None, redirect=None, status=None)) after connection broken by 'SSLError(\"Can't connect to HTTPS URL because the SSL module is not available.\")': /simple/tensorflow/\u001b[0m\u001b[33m\n",
      "\u001b[0m\u001b[33mWARNING: Retrying (Retry(total=1, connect=None, read=None, redirect=None, status=None)) after connection broken by 'SSLError(\"Can't connect to HTTPS URL because the SSL module is not available.\")': /simple/tensorflow/\u001b[0m\u001b[33m\n",
      "\u001b[0m\u001b[33mWARNING: Retrying (Retry(total=0, connect=None, read=None, redirect=None, status=None)) after connection broken by 'SSLError(\"Can't connect to HTTPS URL because the SSL module is not available.\")': /simple/tensorflow/\u001b[0m\u001b[33m\n",
      "\u001b[0mCould not fetch URL https://pypi.org/simple/tensorflow/: There was a problem confirming the ssl certificate: HTTPSConnectionPool(host='pypi.org', port=443): Max retries exceeded with url: /simple/tensorflow/ (Caused by SSLError(\"Can't connect to HTTPS URL because the SSL module is not available.\")) - skipping\n",
      "Requirement already satisfied: tensorflow-macos==2.13.0-rc2 in /Users/carlosroberto/Documentos/Projetos/.conda/lib/python3.11/site-packages (from tensorflow) (2.13.0rc2)\n",
      "Requirement already satisfied: absl-py>=1.0.0 in /Users/carlosroberto/Documentos/Projetos/.conda/lib/python3.11/site-packages (from tensorflow-macos==2.13.0-rc2->tensorflow) (1.4.0)\n",
      "Requirement already satisfied: astunparse>=1.6.0 in /Users/carlosroberto/Documentos/Projetos/.conda/lib/python3.11/site-packages (from tensorflow-macos==2.13.0-rc2->tensorflow) (1.6.3)\n",
      "Requirement already satisfied: flatbuffers>=23.1.21 in /Users/carlosroberto/Documentos/Projetos/.conda/lib/python3.11/site-packages (from tensorflow-macos==2.13.0-rc2->tensorflow) (23.5.26)\n",
      "Requirement already satisfied: gast<=0.4.0,>=0.2.1 in /Users/carlosroberto/Documentos/Projetos/.conda/lib/python3.11/site-packages (from tensorflow-macos==2.13.0-rc2->tensorflow) (0.4.0)\n",
      "Requirement already satisfied: google-pasta>=0.1.1 in /Users/carlosroberto/Documentos/Projetos/.conda/lib/python3.11/site-packages (from tensorflow-macos==2.13.0-rc2->tensorflow) (0.2.0)\n",
      "Requirement already satisfied: h5py>=2.9.0 in /Users/carlosroberto/Documentos/Projetos/.conda/lib/python3.11/site-packages (from tensorflow-macos==2.13.0-rc2->tensorflow) (3.9.0)\n",
      "Requirement already satisfied: libclang>=13.0.0 in /Users/carlosroberto/Documentos/Projetos/.conda/lib/python3.11/site-packages (from tensorflow-macos==2.13.0-rc2->tensorflow) (16.0.0)\n",
      "Requirement already satisfied: numpy>=1.22 in /Users/carlosroberto/Documentos/Projetos/.conda/lib/python3.11/site-packages (from tensorflow-macos==2.13.0-rc2->tensorflow) (1.23.5)\n",
      "Requirement already satisfied: opt-einsum>=2.3.2 in /Users/carlosroberto/Documentos/Projetos/.conda/lib/python3.11/site-packages (from tensorflow-macos==2.13.0-rc2->tensorflow) (3.3.0)\n",
      "Requirement already satisfied: packaging in /Users/carlosroberto/Documentos/Projetos/.conda/lib/python3.11/site-packages (from tensorflow-macos==2.13.0-rc2->tensorflow) (23.1)\n",
      "Requirement already satisfied: protobuf!=4.21.0,!=4.21.1,!=4.21.2,!=4.21.3,!=4.21.4,!=4.21.5,<5.0.0dev,>=3.20.3 in /Users/carlosroberto/Documentos/Projetos/.conda/lib/python3.11/site-packages (from tensorflow-macos==2.13.0-rc2->tensorflow) (4.23.3)\n",
      "Requirement already satisfied: setuptools in /Users/carlosroberto/Documentos/Projetos/.conda/lib/python3.11/site-packages (from tensorflow-macos==2.13.0-rc2->tensorflow) (67.8.0)\n",
      "Requirement already satisfied: six>=1.12.0 in /Users/carlosroberto/Documentos/Projetos/.conda/lib/python3.11/site-packages (from tensorflow-macos==2.13.0-rc2->tensorflow) (1.16.0)\n",
      "Requirement already satisfied: termcolor>=1.1.0 in /Users/carlosroberto/Documentos/Projetos/.conda/lib/python3.11/site-packages (from tensorflow-macos==2.13.0-rc2->tensorflow) (2.3.0)\n",
      "Requirement already satisfied: typing-extensions<4.6.0,>=3.6.6 in /Users/carlosroberto/Documentos/Projetos/.conda/lib/python3.11/site-packages (from tensorflow-macos==2.13.0-rc2->tensorflow) (4.5.0)\n",
      "Requirement already satisfied: wrapt>=1.11.0 in /Users/carlosroberto/Documentos/Projetos/.conda/lib/python3.11/site-packages (from tensorflow-macos==2.13.0-rc2->tensorflow) (1.14.1)\n",
      "Requirement already satisfied: grpcio<2.0,>=1.24.3 in /Users/carlosroberto/Documentos/Projetos/.conda/lib/python3.11/site-packages (from tensorflow-macos==2.13.0-rc2->tensorflow) (1.56.0)\n",
      "Requirement already satisfied: tensorboard<2.14,>=2.13 in /Users/carlosroberto/Documentos/Projetos/.conda/lib/python3.11/site-packages (from tensorflow-macos==2.13.0-rc2->tensorflow) (2.13.0)\n",
      "Requirement already satisfied: tensorflow-estimator<2.14,>=2.13.0rc0 in /Users/carlosroberto/Documentos/Projetos/.conda/lib/python3.11/site-packages (from tensorflow-macos==2.13.0-rc2->tensorflow) (2.13.0)\n",
      "Requirement already satisfied: keras<2.14,>=2.13.1rc0 in /Users/carlosroberto/Documentos/Projetos/.conda/lib/python3.11/site-packages (from tensorflow-macos==2.13.0-rc2->tensorflow) (2.13.1)\n",
      "Requirement already satisfied: wheel<1.0,>=0.23.0 in /Users/carlosroberto/Documentos/Projetos/.conda/lib/python3.11/site-packages (from astunparse>=1.6.0->tensorflow-macos==2.13.0-rc2->tensorflow) (0.38.4)\n",
      "Requirement already satisfied: google-auth<3,>=1.6.3 in /Users/carlosroberto/Documentos/Projetos/.conda/lib/python3.11/site-packages (from tensorboard<2.14,>=2.13->tensorflow-macos==2.13.0-rc2->tensorflow) (2.21.0)\n",
      "Requirement already satisfied: google-auth-oauthlib<1.1,>=0.5 in /Users/carlosroberto/Documentos/Projetos/.conda/lib/python3.11/site-packages (from tensorboard<2.14,>=2.13->tensorflow-macos==2.13.0-rc2->tensorflow) (1.0.0)\n",
      "Requirement already satisfied: markdown>=2.6.8 in /Users/carlosroberto/Documentos/Projetos/.conda/lib/python3.11/site-packages (from tensorboard<2.14,>=2.13->tensorflow-macos==2.13.0-rc2->tensorflow) (3.4.3)\n",
      "Requirement already satisfied: requests<3,>=2.21.0 in /Users/carlosroberto/Documentos/Projetos/.conda/lib/python3.11/site-packages (from tensorboard<2.14,>=2.13->tensorflow-macos==2.13.0-rc2->tensorflow) (2.29.0)\n",
      "Requirement already satisfied: tensorboard-data-server<0.8.0,>=0.7.0 in /Users/carlosroberto/Documentos/Projetos/.conda/lib/python3.11/site-packages (from tensorboard<2.14,>=2.13->tensorflow-macos==2.13.0-rc2->tensorflow) (0.7.1)\n",
      "Requirement already satisfied: werkzeug>=1.0.1 in /Users/carlosroberto/Documentos/Projetos/.conda/lib/python3.11/site-packages (from tensorboard<2.14,>=2.13->tensorflow-macos==2.13.0-rc2->tensorflow) (2.3.6)\n",
      "Requirement already satisfied: cachetools<6.0,>=2.0.0 in /Users/carlosroberto/Documentos/Projetos/.conda/lib/python3.11/site-packages (from google-auth<3,>=1.6.3->tensorboard<2.14,>=2.13->tensorflow-macos==2.13.0-rc2->tensorflow) (5.3.1)\n",
      "Requirement already satisfied: pyasn1-modules>=0.2.1 in /Users/carlosroberto/Documentos/Projetos/.conda/lib/python3.11/site-packages (from google-auth<3,>=1.6.3->tensorboard<2.14,>=2.13->tensorflow-macos==2.13.0-rc2->tensorflow) (0.3.0)\n",
      "Requirement already satisfied: rsa<5,>=3.1.4 in /Users/carlosroberto/Documentos/Projetos/.conda/lib/python3.11/site-packages (from google-auth<3,>=1.6.3->tensorboard<2.14,>=2.13->tensorflow-macos==2.13.0-rc2->tensorflow) (4.9)\n",
      "Requirement already satisfied: urllib3<2.0 in /Users/carlosroberto/Documentos/Projetos/.conda/lib/python3.11/site-packages (from google-auth<3,>=1.6.3->tensorboard<2.14,>=2.13->tensorflow-macos==2.13.0-rc2->tensorflow) (1.26.16)\n",
      "Requirement already satisfied: requests-oauthlib>=0.7.0 in /Users/carlosroberto/Documentos/Projetos/.conda/lib/python3.11/site-packages (from google-auth-oauthlib<1.1,>=0.5->tensorboard<2.14,>=2.13->tensorflow-macos==2.13.0-rc2->tensorflow) (1.3.1)\n",
      "Requirement already satisfied: charset-normalizer<4,>=2 in /Users/carlosroberto/Documentos/Projetos/.conda/lib/python3.11/site-packages (from requests<3,>=2.21.0->tensorboard<2.14,>=2.13->tensorflow-macos==2.13.0-rc2->tensorflow) (2.0.4)\n",
      "Requirement already satisfied: idna<4,>=2.5 in /Users/carlosroberto/Documentos/Projetos/.conda/lib/python3.11/site-packages (from requests<3,>=2.21.0->tensorboard<2.14,>=2.13->tensorflow-macos==2.13.0-rc2->tensorflow) (3.4)\n",
      "Requirement already satisfied: certifi>=2017.4.17 in /Users/carlosroberto/Documentos/Projetos/.conda/lib/python3.11/site-packages (from requests<3,>=2.21.0->tensorboard<2.14,>=2.13->tensorflow-macos==2.13.0-rc2->tensorflow) (2023.5.7)\n",
      "Requirement already satisfied: MarkupSafe>=2.1.1 in /Users/carlosroberto/Documentos/Projetos/.conda/lib/python3.11/site-packages (from werkzeug>=1.0.1->tensorboard<2.14,>=2.13->tensorflow-macos==2.13.0-rc2->tensorflow) (2.1.1)\n",
      "Requirement already satisfied: pyasn1<0.6.0,>=0.4.6 in /Users/carlosroberto/Documentos/Projetos/.conda/lib/python3.11/site-packages (from pyasn1-modules>=0.2.1->google-auth<3,>=1.6.3->tensorboard<2.14,>=2.13->tensorflow-macos==2.13.0-rc2->tensorflow) (0.5.0)\n",
      "Requirement already satisfied: oauthlib>=3.0.0 in /Users/carlosroberto/Documentos/Projetos/.conda/lib/python3.11/site-packages (from requests-oauthlib>=0.7.0->google-auth-oauthlib<1.1,>=0.5->tensorboard<2.14,>=2.13->tensorflow-macos==2.13.0-rc2->tensorflow) (3.2.2)\n",
      "\u001b[33mWARNING: pip is configured with locations that require TLS/SSL, however the ssl module in Python is not available.\u001b[0m\u001b[33m\n",
      "\u001b[0mRequirement already satisfied: lime in /Users/carlosroberto/Documentos/Projetos/.conda/lib/python3.11/site-packages (0.2.0.1)\n",
      "\u001b[33mWARNING: Retrying (Retry(total=4, connect=None, read=None, redirect=None, status=None)) after connection broken by 'SSLError(\"Can't connect to HTTPS URL because the SSL module is not available.\")': /simple/lime/\u001b[0m\u001b[33m\n",
      "\u001b[0m\u001b[33mWARNING: Retrying (Retry(total=3, connect=None, read=None, redirect=None, status=None)) after connection broken by 'SSLError(\"Can't connect to HTTPS URL because the SSL module is not available.\")': /simple/lime/\u001b[0m\u001b[33m\n",
      "\u001b[0m\u001b[33mWARNING: Retrying (Retry(total=2, connect=None, read=None, redirect=None, status=None)) after connection broken by 'SSLError(\"Can't connect to HTTPS URL because the SSL module is not available.\")': /simple/lime/\u001b[0m\u001b[33m\n",
      "\u001b[0m\u001b[33mWARNING: Retrying (Retry(total=1, connect=None, read=None, redirect=None, status=None)) after connection broken by 'SSLError(\"Can't connect to HTTPS URL because the SSL module is not available.\")': /simple/lime/\u001b[0m\u001b[33m\n",
      "\u001b[0m\u001b[33mWARNING: Retrying (Retry(total=0, connect=None, read=None, redirect=None, status=None)) after connection broken by 'SSLError(\"Can't connect to HTTPS URL because the SSL module is not available.\")': /simple/lime/\u001b[0m\u001b[33m\n",
      "\u001b[0mCould not fetch URL https://pypi.org/simple/lime/: There was a problem confirming the ssl certificate: HTTPSConnectionPool(host='pypi.org', port=443): Max retries exceeded with url: /simple/lime/ (Caused by SSLError(\"Can't connect to HTTPS URL because the SSL module is not available.\")) - skipping\n",
      "Requirement already satisfied: matplotlib in /Users/carlosroberto/Documentos/Projetos/.conda/lib/python3.11/site-packages (from lime) (3.7.1)\n",
      "Requirement already satisfied: numpy in /Users/carlosroberto/Documentos/Projetos/.conda/lib/python3.11/site-packages (from lime) (1.23.5)\n",
      "Requirement already satisfied: scipy in /Users/carlosroberto/Documentos/Projetos/.conda/lib/python3.11/site-packages (from lime) (1.10.1)\n",
      "Requirement already satisfied: tqdm in /Users/carlosroberto/Documentos/Projetos/.conda/lib/python3.11/site-packages (from lime) (4.65.0)\n",
      "Requirement already satisfied: scikit-learn>=0.18 in /Users/carlosroberto/Documentos/Projetos/.conda/lib/python3.11/site-packages (from lime) (1.3.0)\n",
      "Requirement already satisfied: scikit-image>=0.12 in /Users/carlosroberto/Documentos/Projetos/.conda/lib/python3.11/site-packages (from lime) (0.21.0)\n",
      "Requirement already satisfied: networkx>=2.8 in /Users/carlosroberto/Documentos/Projetos/.conda/lib/python3.11/site-packages (from scikit-image>=0.12->lime) (3.1)\n",
      "Requirement already satisfied: pillow>=9.0.1 in /Users/carlosroberto/Documentos/Projetos/.conda/lib/python3.11/site-packages (from scikit-image>=0.12->lime) (9.5.0)\n",
      "Requirement already satisfied: imageio>=2.27 in /Users/carlosroberto/Documentos/Projetos/.conda/lib/python3.11/site-packages (from scikit-image>=0.12->lime) (2.31.1)\n",
      "Requirement already satisfied: tifffile>=2022.8.12 in /Users/carlosroberto/Documentos/Projetos/.conda/lib/python3.11/site-packages (from scikit-image>=0.12->lime) (2023.4.12)\n",
      "Requirement already satisfied: PyWavelets>=1.1.1 in /Users/carlosroberto/Documentos/Projetos/.conda/lib/python3.11/site-packages (from scikit-image>=0.12->lime) (1.4.1)\n",
      "Requirement already satisfied: packaging>=21 in /Users/carlosroberto/Documentos/Projetos/.conda/lib/python3.11/site-packages (from scikit-image>=0.12->lime) (23.1)\n",
      "Requirement already satisfied: lazy_loader>=0.2 in /Users/carlosroberto/Documentos/Projetos/.conda/lib/python3.11/site-packages (from scikit-image>=0.12->lime) (0.3)\n",
      "Requirement already satisfied: joblib>=1.1.1 in /Users/carlosroberto/Documentos/Projetos/.conda/lib/python3.11/site-packages (from scikit-learn>=0.18->lime) (1.3.1)\n",
      "Requirement already satisfied: threadpoolctl>=2.0.0 in /Users/carlosroberto/Documentos/Projetos/.conda/lib/python3.11/site-packages (from scikit-learn>=0.18->lime) (3.1.0)\n",
      "Requirement already satisfied: contourpy>=1.0.1 in /Users/carlosroberto/Documentos/Projetos/.conda/lib/python3.11/site-packages (from matplotlib->lime) (1.1.0)\n",
      "Requirement already satisfied: cycler>=0.10 in /Users/carlosroberto/Documentos/Projetos/.conda/lib/python3.11/site-packages (from matplotlib->lime) (0.11.0)\n",
      "Requirement already satisfied: fonttools>=4.22.0 in /Users/carlosroberto/Documentos/Projetos/.conda/lib/python3.11/site-packages (from matplotlib->lime) (4.40.0)\n",
      "Requirement already satisfied: kiwisolver>=1.0.1 in /Users/carlosroberto/Documentos/Projetos/.conda/lib/python3.11/site-packages (from matplotlib->lime) (1.4.4)\n",
      "Requirement already satisfied: pyparsing>=2.3.1 in /Users/carlosroberto/Documentos/Projetos/.conda/lib/python3.11/site-packages (from matplotlib->lime) (3.1.0)\n",
      "Requirement already satisfied: python-dateutil>=2.7 in /Users/carlosroberto/Documentos/Projetos/.conda/lib/python3.11/site-packages (from matplotlib->lime) (2.8.2)\n",
      "Requirement already satisfied: six>=1.5 in /Users/carlosroberto/Documentos/Projetos/.conda/lib/python3.11/site-packages (from python-dateutil>=2.7->matplotlib->lime) (1.16.0)\n"
     ]
    }
   ],
   "source": [
    "! pip install -U sklearn\n",
    "! pip install -U graphviz\n",
    "! pip install -U pandas\n",
    "! pip install -U dtreeviz\n",
    "\n",
    "! pip install -U scikit_learn\n",
    "! pip install -U ydata-profiling\n",
    "! pip install -U plotly\n",
    "! pip install -U nbformat\n",
    "! pip install -U pandas\n",
    "! pip install -U matplotlib\n",
    "! pip install -U regex\n",
    "! pip install -U keras\n",
    "\n",
    "! pip install -U tensorflow\n",
    "! pip install -U  lime"
   ]
  },
  {
   "cell_type": "code",
   "execution_count": null,
   "metadata": {},
   "outputs": [],
   "source": [
    "! pip install --quiet -U sklearn\n",
    "! pip install --quiet -U graphviz\n",
    "! pip install --quiet -U pandas\n",
    "! pip install --quiet -U dtreeviz\n",
    "\n",
    "! pip install --quiet -U scikit_learn\n",
    "! pip install --quiet -U ydata-profiling\n",
    "! pip install --quiet -U plotly\n",
    "! pip install --quiet -U nbformat\n",
    "! pip install --quiet -U pandas\n",
    "! pip install --quiet -U matplotlib\n",
    "! pip install --quiet -U regex\n",
    "! pip install --quiet -U keras\n",
    "\n",
    "! pip install --quiet -U tensorflow\n",
    "! pip install --quiet -U lime\n"
   ]
  },
  {
   "attachments": {},
   "cell_type": "markdown",
   "metadata": {},
   "source": [
    "# Tirar as mensagens\n"
   ]
  },
  {
   "cell_type": "code",
   "execution_count": null,
   "metadata": {},
   "outputs": [],
   "source": [
    "import warnings\n",
    "from sklearn.exceptions import ConvergenceWarning\n",
    "\n",
    "warnings.simplefilter(action=\"ignore\", category=FutureWarning)\n",
    "warnings.simplefilter(\"ignore\", category=ConvergenceWarning)\n",
    "\n",
    "pd.set_option(\"display.max_columns\", None)\n",
    "pd.set_option(\"display.max_rows\", None)\n",
    "pd.set_option(\"display.width\", None)"
   ]
  }
 ],
 "metadata": {
  "kernelspec": {
   "display_name": "Python 3 (ipykernel)",
   "language": "python",
   "name": "python3"
  },
  "language_info": {
   "codemirror_mode": {
    "name": "ipython",
    "version": 3
   },
   "file_extension": ".py",
   "mimetype": "text/x-python",
   "name": "python",
   "nbconvert_exporter": "python",
   "pygments_lexer": "ipython3",
   "version": "3.11.3"
  }
 },
 "nbformat": 4,
 "nbformat_minor": 4
}
